<?xml version="1.0"?>
<robot name="nexus_4wd_mecanum" xmlns:xacro="http://ros.org/wiki/xacro">

  <xacro:property name="PI" value="3.1415926535897931" />

  <xacro:property name="wheel_radius" value="0.050" />
  <xacro:property name="wheel_width" value="0.0505" />

  <material name="yellow"><color rgba="0.8 0.8 0.0 1.0" /></material>
  <material name="black"><color rgba="0.15 0.15 0.15 1.0" /></material>
  <material name="dark_grey"><color rgba="0.2 0.2 0.2 1.0" /></material>
  <material name="light_grey"><color rgba="0.4 0.4 0.4 1.0" /></material>

  <link name="base_footprint"></link>

  <joint name="base_link_joint" type="fixed">
    <origin xyz="0 0 0.05" rpy="0 0 0" />
    <parent link="base_footprint"/>
    <child link="base_link" />
  </joint>

  <link name="base_link">
    <visual>
      <origin xyz="0 0 0" rpy="0 0 0" />
      <geometry>
        <mesh filename="package://nexus_4wd_mecanum_description/meshes/nexus_base_link.STL" scale="0.001 0.001 0.001"/>
      </geometry>
      <material name="yellow" />
    </visual>
    <collision>
      <origin xyz="0 0 0"/>
      <geometry>
        <mesh filename="package://nexus_4wd_mecanum_description/meshes/nexus_base_link_collision.STL" scale="0.001 0.001 0.001"/>
      </geometry>
    </collision>
    <inertial>
      <!-- Inertia from CAD model, filled box assumption -->
      <origin xyz="-0.01103 0 0.002" rpy="0 0 0"/>
      <mass value="2.844"/>
      <inertia
        ixx="0.018819942" ixy="0" ixz="-0.000101519"
        iyy="0.057333716" iyz="0"
        izz="0.074201740"/>
    </inertial>
  </link>

  <joint name="upper_left_wheel_shaft_joint" type="fixed">
    <origin xyz="0.150 0.108 0.0" rpy="0 0 0" />
    <parent link="base_link"/>
    <child link="upper_left_wheel_shaft" />
  </joint>

  <link name="upper_left_wheel_shaft">
    <visual>
      <origin xyz="0 0 0" rpy="0 0 0" />
      <geometry>
        <mesh filename="package://nexus_4wd_mecanum_description/meshes/wheel_shaft.STL" scale="0.001 0.001 0.001"/>
      </geometry>
      <material name="black" />
    </visual>
    <collision>
      <origin xyz="0 0 0"/>
      <geometry>
        <mesh filename="package://nexus_4wd_mecanum_description/meshes/wheel_shaft.STL" scale="0.001 0.001 0.001"/>
      </geometry>
    </collision>
    <inertial>
      <origin xyz="0 0.01221 0" rpy="0 0 0"/>
      <mass value="0.055"/>
      <inertia
        ixx="0.000021370" ixy="0" ixz="0"
        iyy="0.000009966" iyz="0"
        izz="0.000021370"/>
    </inertial>
  </link>

  <joint name="lower_left_wheel_shaft_joint" type="fixed">
    <origin xyz="-0.150 0.108 0.0" rpy="0 0 0" />
    <parent link="base_link"/>
    <child link="lower_left_wheel_shaft" />
  </joint>

  <link name="lower_left_wheel_shaft">
    <visual>
      <origin xyz="0 0 0" rpy="0 0 0" />
      <geometry>
        <mesh filename="package://nexus_4wd_mecanum_description/meshes/wheel_shaft.STL" scale="0.001 0.001 0.001"/>
      </geometry>
      <material name="black" />
    </visual>
    <collision>
      <origin xyz="0 0 0"/>
      <geometry>
        <mesh filename="package://nexus_4wd_mecanum_description/meshes/wheel_shaft.STL" scale="0.001 0.001 0.001"/>
      </geometry>
    </collision>
    <inertial>
      <origin xyz="0 0.01221 0" rpy="0 0 0"/>
      <mass value="0.055"/>
      <inertia
        ixx="0.000021370" ixy="0" ixz="0"
        iyy="0.000009966" iyz="0"
        izz="0.000021370"/>
    </inertial>
  </link>

  <joint name="upper_right_wheel_shaft_joint" type="fixed">
    <origin xyz="0.150 -0.108 0.0" rpy="${PI} 0 0" />
    <parent link="base_link"/>
    <child link="upper_right_wheel_shaft" />
  </joint>

  <link name="upper_right_wheel_shaft">
    <visual>
      <origin xyz="0 0 0" rpy="0 0 0" />
      <geometry>
        <mesh filename="package://nexus_4wd_mecanum_description/meshes/wheel_shaft.STL" scale="0.001 0.001 0.001"/>
      </geometry>
      <material name="black" />
    </visual>
    <collision>
      <origin xyz="0 0 0"/>
      <geometry>
        <mesh filename="package://nexus_4wd_mecanum_description/meshes/wheel_shaft.STL" scale="0.001 0.001 0.001"/>
      </geometry>
    </collision>
    <inertial>
      <origin xyz="0 0.01221 0" rpy="0 0 0"/>
      <mass value="0.055"/>
      <inertia
        ixx="0.000021370" ixy="0" ixz="0"
        iyy="0.000009966" iyz="0"
        izz="0.000021370"/>
    </inertial>
  </link>

  <joint name="lower_right_wheel_shaft_joint" type="fixed">
    <origin xyz="-0.150 -0.108 0.0" rpy="${PI} 0 0" />
    <parent link="base_link"/>
    <child link="lower_right_wheel_shaft" />
  </joint>

  <link name="lower_right_wheel_shaft">
    <visual>
      <origin xyz="0 0 0" rpy="0 0 0" />
      <geometry>
        <mesh filename="package://nexus_4wd_mecanum_description/meshes/wheel_shaft.STL" scale="0.001 0.001 0.001"/>
      </geometry>
      <material name="black" />
    </visual>
    <collision>
      <origin xyz="0 0 0"/>
      <geometry>
        <mesh filename="package://nexus_4wd_mecanum_description/meshes/wheel_shaft.STL" scale="0.001 0.001 0.001"/>
      </geometry>
    </collision>
    <inertial>
      <origin xyz="0 0.01221 0" rpy="0 0 0"/>
      <mass value="0.055"/>
      <inertia
        ixx="0.000021370" ixy="0" ixz="0"
        iyy="0.000009966" iyz="0"
        izz="0.000021370"/>
    </inertial>
  </link>

  <joint name="upper_left_wheel_joint" type="continuous">
    <origin xyz="0 0.042 0" rpy="0 0 0" />
    <parent link="upper_left_wheel_shaft"/>
    <child link="upper_left_wheel" />
    <axis xyz="0 1 0"/>
  </joint>

  <link name="upper_left_wheel">
    <visual>
      <origin xyz="0 0 0" rpy="0 0 0" />
      <geometry>
        <mesh filename="package://nexus_4wd_mecanum_description/meshes/mecanum_wheel_left.STL" scale="0.001 0.001 0.001"/>
      </geometry>
      <material name="light_grey" />
    </visual>
    <collision>
      <origin xyz="0 0 0" rpy="${PI/2} 0 0"/>
      <geometry>
        <cylinder radius="${wheel_radius}" length="${wheel_width}"/>
      </geometry>
    </collision>
    <inertial>
      <origin xyz="0.0 0.0 0.0" rpy="0 0 0"/>
      <mass value="0.3844"/>
      <!-- Inertia based on cylinder -->
      <inertia
        ixx="0.000324824" ixy="0" ixz="0"
        iyy="0.000480000" iyz="0"
        izz="0.000324824"/>
    </inertial>
  </link>

  <joint name="lower_left_wheel_joint" type="continuous">
    <origin xyz="0 0.042 0" rpy="0 0 0" />
    <parent link="lower_left_wheel_shaft"/>
    <child link="lower_left_wheel" />
    <axis xyz="0 1 0"/>
  </joint>

  <link name="lower_left_wheel">
    <visual>
      <origin xyz="0 0 0" rpy="0 0 0" />
      <geometry>
        <mesh filename="package://nexus_4wd_mecanum_description/meshes/mecanum_wheel_right.STL" scale="0.001 0.001 0.001"/>
      </geometry>
      <material name="light_grey" />
    </visual>
    <collision>
      <origin xyz="0 0 0" rpy="${PI/2} 0 0"/>
      <geometry>
        <cylinder radius="${wheel_radius}" length="${wheel_width}"/>
      </geometry>
    </collision>
    <inertial>
      <origin xyz="0.0 0.0 0.0" rpy="0 0 0"/>
      <mass value="0.3844"/>
      <!-- Inertia based on cylinder -->
      <inertia
        ixx="0.000324824" ixy="0" ixz="0"
        iyy="0.000480000" iyz="0"
        izz="0.000324824"/>
    </inertial>
  </link>

  <joint name="upper_right_wheel_joint" type="continuous">
    <origin xyz="0 0.042 0" rpy="0 0 0" />
    <parent link="upper_right_wheel_shaft"/>
    <child link="upper_right_wheel" />
    <axis xyz="0 1 0"/>
  </joint>

  <link name="upper_right_wheel">
    <visual>
      <origin xyz="0 0 0" rpy="0 0 0" />
      <geometry>
        <mesh filename="package://nexus_4wd_mecanum_description/meshes/mecanum_wheel_right.STL" scale="0.001 0.001 0.001"/>
      </geometry>
      <material name="light_grey" />
    </visual>
    <collision>
      <origin xyz="0 0 0" rpy="${PI/2} 0 0"/>
      <geometry>
        <cylinder radius="${wheel_radius}" length="${wheel_width}"/>
      </geometry>
    </collision>
    <inertial>
      <origin xyz="0.0 0.0 0.0" rpy="0 0 0"/>
      <mass value="0.3844"/>
      <!-- Inertia based on cylinder -->
      <inertia
        ixx="0.000324824" ixy="0" ixz="0"
        iyy="0.000480000" iyz="0"
        izz="0.000324824"/>
    </inertial>
  </link>

  <joint name="lower_right_wheel_joint" type="continuous">
    <origin xyz="0 0.042 0" rpy="0 0 0" />
    <parent link="lower_right_wheel_shaft"/>
    <child link="lower_right_wheel" />
    <axis xyz="0 1 0"/>
  </joint>

  <link name="lower_right_wheel">
    <visual>
      <origin xyz="0 0 0" rpy="0 0 0" />
      <geometry>
        <mesh filename="package://nexus_4wd_mecanum_description/meshes/mecanum_wheel_left.STL" scale="0.001 0.001 0.001"/>
      </geometry>
      <material name="light_grey" />
    </visual>
    <collision>
      <origin xyz="0 0 0" rpy="${PI/2} 0 0"/>
      <geometry>
        <cylinder radius="${wheel_radius}" length="${wheel_width}"/>
      </geometry>
    </collision>
    <inertial>
      <origin xyz="0.0 0.0 0.0" rpy="0 0 0"/>
      <mass value="0.3844"/>
      <!-- Inertia based on cylinder -->
      <inertia
        ixx="0.000324824" ixy="0" ixz="0"
        iyy="0.000480000" iyz="0"
        izz="0.000324824"/>
    </inertial>
  </link>

  <joint name="left_sensor_joint" type="fixed">
    <origin xyz="0 0.108 0.010" rpy="0 0 ${PI/2}" />
    <parent link="base_link"/>
    <child link="left_sensor" />
  </joint>

  <link name="left_sensor">
    <visual>
      <origin xyz="0 0 0" rpy="${PI/2} 0 0" />
      <geometry>
        <mesh filename="package://nexus_4wd_mecanum_description/meshes/urm04.STL" scale="0.001 0.001 0.001"/>
      </geometry>
      <material name="black" />
    </visual>
  </link>

  <joint name="front_sensor_joint" type="fixed">
    <origin xyz="0.205 0 0.010" rpy="0 0 0" />
    <parent link="base_link"/>
    <child link="front_sensor" />
  </joint>

  <link name="front_sensor">
    <visual>
      <origin xyz="0 0 0" rpy="${PI/2} 0 0" />
      <geometry>
        <mesh filename="package://nexus_4wd_mecanum_description/meshes/urm04.STL" scale="0.001 0.001 0.001"/>
      </geometry>
      <material name="black" />
    </visual>
  </link>

  <joint name="right_sensor_joint" type="fixed">
    <origin xyz="0 -0.108 0.010" rpy="0 0 ${-PI/2}" />
    <parent link="base_link"/>
    <child link="right_sensor" />
  </joint>

  <link name="right_sensor">
    <visual>
      <origin xyz="0 0 0" rpy="${PI/2} 0 0" />
      <geometry>
        <mesh filename="package://nexus_4wd_mecanum_description/meshes/urm04.STL" scale="0.001 0.001 0.001"/>
      </geometry>
      <material name="black" />
    </visual>
  </link>

  <joint name="rear_sensor_joint" type="fixed">
    <origin xyz="-0.201 0 0.010" rpy="0 0 ${PI}" />
    <parent link="base_link"/>
    <child link="rear_sensor" />
  </joint>

  <link name="rear_sensor">
    <visual>
      <origin xyz="0 0 0" rpy="${PI/2} 0 0" />
      <geometry>
        <mesh filename="package://nexus_4wd_mecanum_description/meshes/urm04.STL" scale="0.001 0.001 0.001"/>
      </geometry>
      <material name="black" />
    </visual>
  </link>

  <link name="plate_link">
    <inertial>
      <origin
        xyz="0.118194757262245 -0.00844020076328886 -0.0612822594819591"
        rpy="0 0 0" />
      <mass value="0.054" />
      <inertia
        ixx="3.465E-05"
        ixy="5.47239752789428E-21"
        ixz="-2.69326661667124E-21"
        iyy="3.465E-05"
        iyz="-4.0386530925085E-21"
        izz="3.69E-05" />
    </inertial>
    <visual>
      <origin xyz="0 0 0" rpy="0 0 0" />
      <geometry>
        <mesh filename="package://nexus_4wd_mecanum_description/meshes/joint.STL" />
      </geometry>
      <material name="">
        <color rgba="0.792156862745098 0.819607843137255 0.933333333333333 1" />
      </material>
    </visual>
    <collision>
      <origin xyz="0 0 0" rpy="0 0 0" />
      <geometry>
        <mesh filename="package://nexus_4wd_mecanum_description/meshes/joint.STL" />
      </geometry>
    </collision>
  </link>

  <joint name="plate_base" type="fixed">
    <origin xyz="-0.025 -0.008 -0.004" rpy="${PI/2} 0 0" />
    <parent link="base_link" />
    <child link="plate_link" />
    <axis xyz="0 0 1" />
  </joint>

  <link name="plate">
    <inertial>
      <origin
        xyz="0.0183189655172414 -2.42861286636753E-17 0.00611197247335394"
        rpy="0 0 0" />
      <mass value="0.696" />
      <inertia
        ixx="0.00285380905172414"
        ixy="7.5844954052083E-19"
        ixz="-0.000469881465517241"
        iyy="0.00164274224137931"
        iyz="3.65449873336129E-19"
        izz="0.00281453318965517" />
    </inertial>
    <visual>
      <origin xyz="0 0 0" rpy="0 0 0" />
      <geometry>
        <mesh filename="package://nexus_4wd_mecanum_description/meshes/plate.STL" />
      </geometry>
      <material
        name="">
        <color rgba="0.792156862745098 0.819607843137255 0.933333333333333 1" />
      </material>
    </visual>
    <collision>
      <origin xyz="0 0 0" rpy="0 0 0" />
      <geometry>
        <mesh filename="package://nexus_4wd_mecanum_description/meshes/plate.STL" />
      </geometry>
    </collision>
  </link>

  <joint name="plate_joint" type="prismatic">
    <origin xyz="0.118 0.115 -0.0085" rpy="${3*PI/2} ${PI} 0" />
    <parent link="plate_link" />
    <child link="plate" />
    <axis xyz="0 0 1" />
    <limit lower="0" upper="0.06" effort="1000" velocity="0.2" />
  </joint>
  
  <transmission name="lift_transmission">
    <type>transmission_interface/SimpleTransmission</type>
    <joint name="plate_joint">
      <hardwareInterface>hardware_interface/VelocityJointInterface </hardwareInterface>
    </joint>  
    <actuator name="lift_motor">
      <hardwareInterface>PositionJointInterface</hardwareInterface>
      <mechanicalReduction>1</mechanicalReduction>
    </actuator>
  </transmission>

  <!-- Include controller plugin for Gazebo -->
  <xacro:include filename="$(find nexus_4wd_mecanum_description)/urdf/nexus_4wd_mecanum.gazebo" />

  <!-- Include URM04 ultrasonic range finders -->
  <xacro:include filename="$(find nexus_4wd_mecanum_description)/urdf/urm04_sensor.xacro"/>
  <!-- front sensor -->
  <xacro:urm04_sensor frame_name="front_sensor" ros_topic="front_sensor" update_rate="10" min_range="0.04" max_range="2.5" horizontal_field_of_view="1.04" vertical_field_of_view="0.04" ray_count="2" />
  <!-- left sensor -->
  <xacro:urm04_sensor frame_name="left_sensor" ros_topic="left_sensor" update_rate="10" min_range="0.04" max_range="2.5" horizontal_field_of_view="1.04" vertical_field_of_view="0.04" ray_count="2" />
  <!-- right sensor -->
  <xacro:urm04_sensor frame_name="right_sensor" ros_topic="right_sensor" update_rate="10" min_range="0.04" max_range="2.5" horizontal_field_of_view="1.04" vertical_field_of_view="0.04" ray_count="2" />
  <!-- rear sensor -->
  <xacro:urm04_sensor frame_name="rear_sensor" ros_topic="rear_sensor" update_rate="10" min_range="0.04" max_range="2.5" horizontal_field_of_view="1.04" vertical_field_of_view="0.04" ray_count="2" />

</robot>
